Workbook

Sheet Assumptions
B2: Forecasted Commodity Price (USD) | C2: 2024 | D2: 2025 | E2: 2026 | F2: 2027 | G2: 2028 | H2: G% F 5yr
B3: Iron Ore | C3: =C4*(1+(0.6*C5+0.4*C6)) -> 114.5045 | D3: =D4*(1+(0.6*D5+0.4*D6)) -> 100.02861 | E3: =E4*(1+(0.6*E5+0.4*E6)) -> 89.492095 | F3: =F4*(1+(0.6*F5+0.4*F6)) -> 86.93938 | G3: =G4*(1+(0.6*G5+0.4*G6)) -> 87.622205 | I3: china steel demand/ infrastructure
B4: Iron Ore Price Assumption 1 | C4: 109 | D4: 95.22 | E4: 85.19 | F4: 82.76 | G4: 83.41 | H4: Ibis world
B5: Iron Ore Price Assumption 2 | C5: 0.0465 | D5: 0.0465 | E5: 0.0465 | F5: 0.0465 | G5: 0.0465 | H5: https://www.technavio.com/report/infrastructure-market-industry-analysis#:~:text=The%20China%20Infrastructure%20Market%20size,4.65%25%20between%202023%20and%202028.
B6: Iron Ore Price Assumption 3 | C6: 0.0565 | D6: 0.0565 | E6: 0.0565 | F6: 0.0565 | G6: 0.0565 | H6: https://www.technavio.com/report/iron-and-steel-market-industry-analysis
B7: Copper | C7: =C8*(1+C9) -> 8940.6821 | D7: =D8*(1+D9) -> 8787.4067 | E7: =E8*(1+E9) -> 7845.8999 | F7: =F8*(1+F9) -> 8134.2032 | G7: =G8*(1+G9) -> 8413.5871 | I7: Electric vehicle data
B8: Copper Price Assumption 1 | C8: 8750.79 | D8: 8600.77 | E8: 7679.26 | F8: 7961.44 | G8: 8234.89 | H8: Ibis World
B9: Copper Price Assumption 2 | C9: 0.0217 | D9: 0.0217 | E9: 0.0217 | F9: 0.0217 | G9: 0.0217 | H9: https://www.statista.com/outlook/mmo/electric-vehicles/china
B10: Aluminium | C10: =C11*(1+C12) -> 2524.2672 | D10: =D11*(1+D12) -> 2655.8448 | E10: =E11*(1+E12) -> 2777.3984 | F10: =F11*(1+F12) -> 2875.096 | G10: =G11*(1+G12) -> 2970.3296 | I10: manufacting index
B11: Aluminium Price Assumption 1 | C11: 2253.81 | D11: 2371.29 | E11: 2479.82 | F11: 2567.05 | G11: 2652.08 | H11: Ibis World
B12: Aluminium Price Assumption 2 | C12: 0.12 | D12: 0.12 | E12: 0.12 | F12: 0.12 | G12: 0.12 | H12: Workspace | I12: China 10yr PPI average of median and average
B13: Others
B14: Productions (Millions) | P14: YoY growth of production (millions of tonnes)
B15: Iron ore | C15: =E47 -> 321.349 | D15: =C15*(1+0.05) -> 337.41645 | E15: =D15*(1+0.075) -> 362.72268 | F15: =E15*(1+0.1) -> 398.99495 | G15: =F15*(1+0.125) -> 448.86932 | H15: From 2026, Simandou kicks in -> 7.5% increasing to 12,5% | P15: =SUM(C15:C16) -> 321.589 | Q15: =SUM(D15:D16) -> 337.66605 | R15: =SUM(E15:E16) -> 362.98227 | S15: =SUM(F15:F16) -> 399.24455 | T15: =SUM(G15:G16) -> 449.15009
B16: Copper | C16: =E48 -> 0.24 | D16: =C16*(1+0.04) -> 0.2496 | E16: =D16*(1+0.04) -> 0.259584 | F16: =C16*(1+0.04) -> 0.2496 | G16: 0.28076605 | H16: From Strategic report: CAGR of 3% till 2028 - Assumption= 4% | Q16: =(Q15-P15)/P15 -> 0.049992537 | R16: =(R15-Q15)/Q15 -> 0.074974128 | S16: =(S15-R15)/R15 -> 0.09990098 | T16: =(T15-S15)/S15 -> 0.12499991
B17: Al | C17: =E49 -> 3.4 | D17: 3.4 | E17: 3.4 | F17: 3.4 | G17: 3.4 | H17: Flat
B18: Other | H18: Flat 10% of annual revenue
B19: Rev (Billions)
B20: Iron Ore | C20: =C3*C15 -> 36795.907 | D20: =D3*D15 -> 33751.298 | E20: =E3*E15 -> 32460.813 | F20: =F3*F15 -> 34688.374 | G20: =G3*G15 -> 39330.92
B21: Copper | C21: =C16*C7 -> 2145.7637 | D21: =D8*D16 -> 2146.7522 | E21: =E8*E16 -> 1993.413 | F21: =F8*F16 -> 1987.1754 | G21: =G8*G16 -> 2312.0776
B22: Al | C22: =C10*C17 -> 8582.5085 | D22: =D10*D17 -> 9029.8723 | E22: =E10*E17 -> 9443.1546 | F22: =F10*F17 -> 9775.3264 | G22: =G10*G17 -> 10099.121
B23: Other | C23: =(C20+C21+C22)*0.1 -> 4752.4179 | D23: =(D20+D21+D22)*0.1 -> 4492.7923 | E23: =(E20+E21+E22)*0.1 -> 4389.738 | F23: =(F20+F21+F22)*0.1 -> 4645.0876 | G23: =(G20+G21+G22)*0.1 -> 5174.2118
B24: Total USD | C24: =SUM(C20:C23) -> 52276.597 | D24: =SUM(D20:D23) -> 49420.715 | E24: =SUM(E20:E23) -> 48287.119 | F24: =SUM(F20:F23) -> 51095.963 | G24: =SUM(G20:G23) -> 56916.33
B25: Total AUD | C25: =C24*C26 -> 79110.174 | D25: =D24*$C$26 -> 74788.368 | E25: =E24*$C$26 -> 73072.896 | F25: =F24*$C$26 -> 77323.521 | G25: =G24*$C$26 -> 86131.482
B26: USD/AUD | C26: 1.5133
B28: Costs Assumptions
B29: INFLATION | C29: 0.0353 | D29: 0.0298 | E29: 0.0268 | F29: 0.0268 | G29: 0.0257 | H29: Australia
B30: INFLATION | C30: 0.0594 | D30: 0.0451 | E30: 0.0373 | F30: 0.0347 | G30: 0.034 | H30: Global
B31: Total Inflation Proxy | C31: =C63 -> -0.036 | D31: =D63 -> 0.035491485 | E31: =E63 -> 0.072855986 | F31: =F63 -> 0.032904734 | G31: =G63 -> 0.064854267
B32: Energy Prices
B33: INT EXP | D33: Average H + adjustment for inflation
B34: DEP + AM | D34: Steady increase + in 2024 +34% expenditure in PP&E -> Expectation of higher increase in 2025 and later
B36: EBITDA | D36: 1st half 2024 | E36: 2nd half 2024 | F36: 2025 | G36: 2026-2028
D37: 12.1 | E37: =12.1-0.2 -> 11.9 | F37: follow increase of exp | G37: Flat growth increase
D38: =SUM(D37:E37) -> 24 | F38: in PP&E (50%)
B40: China Steel
B44: Reality + Assumptions 2024
B45: Exp Year | C45: 2024 | D45: Assumption yearly production | F45: Prod Sem 2
C46: Production Sem 1
A47: Iron ore | B47: 323-338 | C47: 158.3 | D47: 2x Sem 1 + 3% | E47: =F47+C47 -> 321.349 | F47: =C47*1.03 -> 163.049
...

Sheet Income Statement
B1: 2018 | C1: 2019 | D1: 2020 | E1: 2021 | F1: 2022 | G1: 2023 | H1: 2024e | I1: 2025e | J1: 2026e | K1: 2027e | L1: 2028e
A2: REVENUES | B2: 54.29 | C2: 62.11 | D2: 64.84 | E2: 84.61 | F2: 80.14 | G2: 81.42 | H2: =Assumptions!C25/1000 -> 79.110174 | I2: =Assumptions!D25/1000 -> 74.788368 | J2: =Assumptions!E25/1000 -> 73.072896 | K2: =Assumptions!F25/1000 -> 77.323521 | L2: =Assumptions!G25/1000 -> 86.131482
A3: H growth | C3: =(C2-B2)/B2 -> 0.14404126 | D3: =(D2-C2)/C2 -> 0.043954275 | E3: =(E2-D2)/D2 -> 0.30490438 | F3: =(F2-E2)/E2 -> -0.052830635 | G3: =(G2-F2)/F2 -> 0.015972049 | H3: =(H2-G2)/G2 -> -0.028369274 | I3: =(I2-H2)/H2 -> -0.054630208 | J3: =(J2-I2)/I2 -> -0.022937685 | ... L3: =(L2-K2)/K2 -> 0.1139105
A5: Cost of Op. Rev | B5: 22.83 | C5: 23.8 | D5: 21.44 | E5: 24.13 | F5: 31.34 | G5: 33.85 | H5: =G5*(1+Assumptions!C31) -> 32.6314 | I5: =H5*(1+Assumptions!D31) -> 33.789537 | J5: =I5*(1+Assumptions!E31) -> 36.251307 | K5: =J5*(1+Assumptions!F31) -> 37.444146 | L5: =K5*(1+Assumptions!G31) -> 39.872559
A6: H growth | C6: =(C5-B5)/B5 -> 0.042487954 | D6: =(D5-C5)/C5 -> -0.099159664 | E6: =(E5-D5)/D5 -> 0.12546642 | F6: =(F5-E5)/E5 -> 0.29879818 | G6: =(G5-F5)/F5 -> 0.080089343 | H6: =(H5-G5)/G5 -> -0.036 | I6: =(I5-H5)/H5 -> 0.035491485 | J6: =(J5-I5)/I5 -> 0.072855986 | ... L6: =(L5-K5)/K5 -> 0.064854267 | O6: Growth h | P6: 0.08594
A7: Com size | C7: =(C5/C2) -> 0.38319111 | D7: =(D5/D2) -> 0.33066009 | E7: =(E5/E2) -> 0.28519088 | F7: =(F5/F2) -> 0.39106564 | G7: =(G5/G2) -> 0.41574552 | H7: =H5/H2 -> 0.41248045 | I7: =I5/I2 -> 0.45180203 | J7: =J5/J2 -> 0.49609785 | K7: =K5/K2 -> 0.48425299 | L7: =L5/L2 -> 0.46292666 | O7: Average size | P7: =AVERAGE(C7:G7) -> 0.36117065 | R7: Average F | S7: =AVERAGE(H7:L7) -> 0.461512
A9: Gross Profit | B9: =B2-B5 -> 31.46 | C9: =C2-C5 -> 38.31 | D9: =D2-D5 -> 43.4 | E9: =E2-E5 -> 60.48 | F9: =F2-F5 -> 48.8 | G9: =G2-G5 -> 47.57 | H9: =H2-H5 -> 46.478774 | I9: =I2-I5 -> 40.998832 | ... L9: =L2-L5 -> 46.258923
A10: H growth | C10: =(C9-B9)/B9 -> 0.21773681 | D10: =(D9-C9)/C9 -> 0.13286348 | E10: =(E9-D9)/D9 -> 0.39354839 | F10: =(F9-E9)/E9 -> -0.19312169 | G10: =(G9-F9)/F9 -> -0.025204918 | H10: =(H9-G9)/G9 -> -0.02293938 | I10: =(I9-H9)/H9 -> -0.11790204 | J10: =(J9-I9)/I9 -> -0.10188686 | ... L10: =(L9-K9)/K9 -> 0.15997111
A11: Com size | C11: =1-C7 -> 0.61680889 | D11: =1-D7 -> 0.66933991 | E11: =1-E7 -> 0.71480912 | F11: =1-F7 -> 0.60893436 | G11: =1-G7 -> 0.58425448 | H11: =1-H7 -> 0.58751955 | I11: =1-I7 -> 0.54819797 | J11: =1-J7 -> 0.50390215 | ... L11: =1-L7 -> 0.53707334 | O11: Average size | P11: =AVERAGE(C11:G11) -> 0.63882935 | R11: Average F | S11: =AVERAGE(H11:L11) -> 0.538488
A13: SGA | B13: 10.51 | C13: 11.208 | D13: 11.44 | E13: 12.76 | F13: 14.6 | G13: 16.41 | H13: =$P$13*H2 -> 14.374319 | I13: =$P$13*I2 -> 13.589047 | J13: =$P$13*J2 -> 13.277345 | K13: =$P$13*K2 -> 14.049684 | L13: =$P$13*L2 -> 15.65009 | O13: Average H | P13: 0.1817 | R13: Average F | S13: 0.1817
A14: Other Exp | B14: 2.8 | C14: 4.28 | D14: 4.28 | E14: 6.52 | F14: 4.3 | G14: 5.73 | H14: =H2*0.0595 -> 4.7070553 | I14: =I2*0.0595 -> 4.4499079 | J14: =J2*0.0595 -> 4.3478373 | K14: =K2*0.0595 -> 4.6007495 | L14: =L2*0.0595 -> 5.1248232 | O14: Average H | P14: 0.0595 | R14: Average F | S14: 0.0595
A16: Op. exp. Total | B16: =SUM(B5,B13:B14) -> 36.14 | C16: =SUM(C5,C13:C14) -> 39.288 | D16: =SUM(D5,D13:D14) -> 37.16 | E16: =SUM(E5,E13:E14) -> 43.41 | F16: =SUM(F5,F13:F14) -> 50.24 | G16: =SUM(G5,G13:G14) -> 55.99 | H16: =SUM(H5,H13:H14) -> 51.712774 | I16: =SUM(I5,I13:I14) -> 51.828491 | ... L16: =SUM(L5,L13:L14) -> 60.647473
C17: =C16/C2 -> 0.63255514 | D17: =D16/D2 -> 0.57310302 | E17: =E16/E2 -> 0.51305992 | F17: =F16/F2 -> 0.62690292 | G17: =G16/G2 -> 0.68766888 | H17: =H16/H2 -> 0.65368045 | I17: =I16/I2 -> 0.69300203 | J17: =J16/J2 -> 0.73729785 | ... L17: =L16/L2 -> 0.70412666 | O17: Average H | P17: =AVERAGE(C17:G17) -> 0.60665798 | R17: Average F | S17: =AVERAGE(H17:L17) -> 0.702712
A19: EBIT | B19: =B9-B13-B14 -> 18.15 | C19: =C9-C13-C14 -> 22.822 | D19: =D9-D13-D14 -> 27.68 | E19: =E9-E13-E14 -> 41.2 | F19: =F9-F13-F14 -> 29.9 | G19: =G9-G13-G14 -> 25.43 | H19: =H9-H13-H14 -> 27.3974 | I19: =I9-I13-I14 -> 22.959877 | ... L19: =L9-L13-L14 -> 25.484009
A20: Com size | C20: =C19/C2 -> 0.36744486 | D20: =D19/D2 -> 0.42689698 | E20: =E19/E2 -> 0.48694008 | F20: =F19/F2 -> 0.37309708 | G20: =G19/G2 -> 0.31233112 | H20: =H19/H2 -> 0.34631955 | I20: =I19/I2 -> 0.30699797 | J20: =J19/J2 -> 0.26270215 | ... L20: =L19/L2 -> 0.29587334 | O20: Average H | P20: =AVERAGE(C20:G20) -> 0.39334202 | R20: Aveareg F | S20: =AVERAGE(H20:L20) -> 0.297288
A22: Int expense | B22: =B19-B25 -> -5.504 | C22: =C19-C25 -> 7.258 | D22: =D19-D25 -> 6.257 | E22: =E19-E25 -> 1.502 | F22: =F19-F25 -> 4.101 | G22: =G19-G25 -> 5.678 | H22: =P22 -> 4.9592 | I22: =H22*(1+Assumptions!D29) -> 5.1069842 | J22: =I22*(1+Assumptions!E29) -> 5.2438513 | K22: =J22*(1+Assumptions!F29) -> 5.3843866 | L22: =K22*(1+Assumptions!G29) -> 5.5227653 | O22: Average H | P22: =AVERAGE(C22:G22) -> 4.9592
A23: plus others | C23: =(C22-B22)/-B22 -> 2.3186773 | D23: =(D22-C22)/C22 -> -0.13791678 | E23: =(E22-D22)/D22 -> -0.75994886 | F23: =(F22-E22)/E22 -> 1.7303595 | G23: =(G22-F22)/F22 -> 0.38454036
A25: Pre tax Income | B25: 23.654 | C25: 15.564 | D25: 21.423 | E25: 39.698 | F25: 25.799 | G25: 19.752 | H25: =H19-H22 -> 22.4382 | I25: =I19-I22 -> 17.852893 | J25: =J19-J22 -> 13.952556 | K25: =K19-K22 -> 15.844555 | L25: =L19-L22 -> 19.961244
C26: =C25/C2 -> 0.25058767 | D26: =D25/D2 -> 0.3303979 | E26: =E25/E2 -> 0.46918804 | F26: =F25/F2 -> 0.32192413 | G26: =G25/G2 -> 0.24259396 | O26: Average H | P26: =AVERAGE(C26:G26) -> 0.32293834
A28: Tax rate | H28: 0.3 | I28: 0.3 | J28: 0.3 | K28: 0.3 | L28: 0.3
A31: Net Income | B31: 15.154 | C31: 17.875 | D31: 28.137 | E31: 14.199 | F31: 11.525 | G31: 18.274 | H31: =H25*(1-H28) -> 15.70674 | I31: =I25*(1-I28) -> 12.497025 | J31: =J25*(1-J28) -> 9.7667889 | K31: =K25*(1-K28) -> 11.091188 | L31: =L25*(1-L28) -> 13.972871
A34: Dep + AM | B34: 5.379 | C34: 6.308 | D34: 6.219 | E34: 6.259 | F34: 7.227 | G34: 8.037 | H34: =G34*(1+$Q$36) -> 8.7586829 | I34: =H34*(1+$Q$36) -> 9.5451694 | J34: =I34*(1+$Q$36) -> 10.402279 | K34: =J34*(1+$Q$36) -> 11.336352 | L34: =K34*(1+$Q$36) -> 12.3543
A35: Gr | C35: =(C34-B34)/B34 -> 0.17270868 | D35: =(D34-C34)/C34 -> -0.014109068 | E35: =(E34-D34)/D34 -> 0.0064319022 | F35: =(F34-E34)/E34 -> 0.15465729 | G35: =(G34-F34)/F34 -> 0.1120797 | O35: Average H | P35: =AVERAGE(C35:G35) -> 0.086353702
A36: Common size | B36: =B34/B2 -> 0.09907902 | C36: =C34/C2 -> 0.10156175 | D36: =D34/D2 -> 0.095913017 | E36: =E34/E2 -> 0.073974707 | F36: =F34/F2 -> 0.090179686 | G36: =G34/G2 -> 0.098710391 | O36: Average H | P36: =AVERAGE(B36:G36) -> 0.093236428 | Q36: =AVERAGE(P35:P36) -> 0.089795065
A38: EBITDA | B38: =SUM(B19,B34) -> 23.529 | C38: =SUM(C19,C34) -> 29.13 | D38: =SUM(D19,D34) -> 33.899 | E38: =SUM(E19,E34) -> 47.459 | F38: =SUM(F19,F34) -> 37.127 | G38: =SUM(G19,G34) -> 33.467 | H38: =H19+H34 -> 36.156083 | I38: =I19+I34 -> 32.505047 | J38: =J19+J34 -> 29.598685 | K38: =K19+K34 -> 32.565293 | L38: =L19+L34 -> 37.838309
A39: (2024 in assumptions)

Sheet Balance Sheet
A1: Billions | B1: 2018 | C1: 2019 | D1: 2020 | E1: 2021 | F1: 2022 | G1: 2023 | H1: 2024e | I1: 2025e | J1: 2026e | K1: 2027e | L1: 2028e | M1: Historical Growth % | N1: Forcast equation
A2: Cash | C2: 15.15 | D2: 16.97 | E2: 21.06 | F2: 13.07 | G2: 15.79 | H2: =G2+(M2*0.33)+(Q3*0.33)+(H47+0.33) -> 17.24591 | I2: =H2+(M2+Q3+H47) -> 18.403623 | J2: =I2+(M2+Q3+H47) -> 19.561335 | K2: =J2+(M2+Q3+H47) -> 20.719048 | L2: =K2+(M2+Q3+H47) -> 21.876761 | M2: =AVERAGE(D3:G3) -> 0.047465882
D3: =(D2-C2)/C2 -> 0.12013201 | E3: =(E2-D2)/D2 -> 0.24101355 | F3: =(F2-E2)/E2 -> -0.37939221 | G3: =(G2-F2)/F2 -> 0.20811018
A4: Receivables | C4: 1.01 | D4: 1.03 | E4: 1.11 | F4: 1.24 | G4: 1.31 | H4: =G4*(1+$M$4) -> 1.3987658 | I4: =H4*(1+$M$4) -> 1.4935464 | J4: =I4*(1+$M$4) -> 1.5947493 | K4: =J4*(1+$M$4) -> 1.7028098 | L4: =K4*(1+$M$4) -> 1.8181924 | M4: =AVERAGE(D5:G5) -> 0.067760153
D5: =(D4-C4)/C4 -> 0.01980198 | E5: =(E4-D4)/D4 -> 0.077669903 | F5: =(F4-E4)/E4 -> 0.11711712 | G5: =(G4-F4)/F4 -> 0.056451613 | H5: =(H6/365)*'Balance Sheet'!H2 -> 1.31 | I5: =(I6/365)*'Balance Sheet'!I2 -> 1.3987658 | J5: =(J6/365)*'Balance Sheet'!J2 -> 1.4935464 | K5: =(K6/365)*'Balance Sheet'!K2 -> 1.5947493 | L5: =(L6/365)*'Balance Sheet'!L2 -> 1.7028098 | M5: =AVERAGE(C4:G4) -> 1.14
A6: Forcast based off assumptions | H6: =(G4/'Balance Sheet'!H2)*365 -> 27.725414 | I6: =(H4/'Balance Sheet'!I2)*365 -> 27.741794 | J6: =(I4/'Balance Sheet'!J2)*365 -> 27.868467 | K6: =(J4/'Balance Sheet'!K2)*365 -> 28.094124 | L6: =(K4/'Balance Sheet'!L2)*365 -> 28.410311
A7: Inventories | C7: 4.93 | D7: 5.09 | E7: 7.49 | F7: 9.12 | G7: 9.78 | H7: 10 | I7: 11 | J7: 12 | K7: 13 | L7: 12 | M7: =AVERAGE(D8:G8) -> 0.19848976
D8: =(D7-C7)/C7 -> 0.032454361 | E8: =(E7-D7)/D7 -> 0.47151277 | F8: =(F7-E7)/E7 -> 0.2176235 | G8: =(G7-F7)/F7 -> 0.072368421
A10: Total Current Assets | C10: 24.64 | D10: 27.11 | E10: 33.65 | F10: 27.85 | G10: 31.59 | H10: =H2+H4+H7 -> 28.644676 | I10: =I2+I4+I7 -> 30.897169 | J10: =J2+J4+J7 -> 33.156085 | K10: =K2+K4+K7 -> 35.421858 | L10: =L2+L4+L7 -> 35.694953 | M10: =AVERAGE(D11:G11) -> 0.075852797
D11: =(D10-C10)/C10 -> 0.10024351 | E11: =(E10-D10)/D10 -> 0.2412394 | F11: =(F10-E10)/E10 -> -0.17236256 | G11: =(G10-F10)/F10 -> 0.13429084
B12: Ratio | C12: =1-(C2+C7)/C10 -> 0.18506494 | D12: =1-(D2+D7)/D10 -> 0.18627813 | E12: =1-(E2+E7)/E10 -> 0.15156018 | F12: =1-(F2+F7)/F10 -> 0.2032316 | G12: =1-(G2+G7)/G10 -> 0.19056664 | M12: =AVERAGE(C12:G12) -> 0.18334029
A13: Property, Plant & Equipment Net Total | C13: 81.71 | D13: 81.73 | E13: 89.43 | F13: 95.02 | G13: 97.6 | H13: =G13*(1+M13*0.33)+(1+Assumptions!C31*0.33)+(1+'Income Statement'!H3*0.33) -> 101.06126 | I13: =H13*(1+M13*0.33)+(1+Assumptions!D31*0.33)+(1+'Income Statement'!I3*0.33) -> 104.59003 | J13: =I13*(1+M13*0.33)+(1+Assumptions!E31*0.33)+(1+'Income Statement'!J3*0.33) -> 108.19519 | K13: =J13*(1+M13*0.33)+(1+Assumptions!F31*0.33)+(1+'Income Statement'!K3*0.33) -> 111.86869 | L13: =K13*(1+M13*0.33)+(1+Assumptions!G31*0.33)+(1+'Income Statement'!L3*0.33) -> 115.62692 | M13: =AVERAGE(D14:G14) -> 0.046029147 | N13: (His% + CPI)*Rev G% | Q13: 161.44 | R13: 159.36 | S13: 174.04 | T13: 186.04 | U13: 197.31
C14: =AVERAGE(C13:G13) -> 89.098 | D14: =(D13-C13)/C13 -> 0.00024476808 | E14: =(E13-D13)/D13 -> 0.094212651 | F14: =(F13-E13)/E13 -> 0.062506989 | G14: =(G13-F13)/F13 -> 0.027152178 | I14: =I13/H13-1 -> 0.0349171 | J14: =J13/I13-1 -> 0.034469401 | K14: =K13/J13-1 -> 0.03395251 | L14: =L13/K13-1 -> 0.033595058 | Q14: 79.73 | R14: 77.63 | S14: 84.61 | T14: 91.03 | U14: 99.7
A16: Other Non-current | C16: 6.4 | D16: 6 | E16: 7.21 | F16: 6.44 | G16: 7.04 | H16: =C17*(1+M16+Q3) -> 6.825703 | I16: =H16*(1+$M$16+$Q$3) -> 7.0399247 | J16: =I16*(1+$M$16+$Q$3) -> 7.2608697 | K16: =J16*(1+$M$16+$Q$3) -> 7.4887489 | L16: =K16*(1+$M$16+$Q$3) -> 7.72378 | M16: =AVERAGE(D17:G17) -> 0.031384563 | N16: (His+CPI)
C17: =AVERAGE(C16:G16) -> 6.618 | D17: =(D16-C16)/C16 -> -0.0625 | E17: =(E16-D16)/D16 -> 0.20166667 | F17: =(F16-E16)/E16 -> -0.10679612 | G17: =(G16-F16)/F16 -> 0.093167702
A18: property + other to total non current asset total ratio | C18: =1-(C13+C16)/C19 -> 0.12249776 | D18: =1-(D13+D16)/D19 -> 0.11802554 | E18: =1-(E13+E16)/E19 -> 0.10584752 | F18: =1-(F13+F16)/F19 -> 0.11148087 | G18: =1-(G13+G16)/G19 -> 0.13140201 | M18: =AVERAGE(C18:G18) -> 0.11785074
A19: Total Non-current Assets | C19: 100.41 | D19: 99.47 | E19: 108.08 | F19: 114.19 | G19: 120.47 | H19: =H13+H16 -> 107.88697 | I19: =I13+I16 -> 111.62996 | J19: =J13+J16 -> 115.45606 | K19: =K13+K16 -> 119.35743 | L19: =L13+L16 -> 123.3507 | M19: =AVERAGE(D20:G20) -> 0.04718135
D20: =(D19-C19)/C19 -> -0.0093616174 | E20: =(E19-D19)/D19 -> 0.086558761 | F20: =(F19-E19)/E19 -> 0.056532198 | G20: =(G19-F19)/F19 -> 0.054996059
A21: Total Assets | C21: 125.06 | D21: 126.58 | E21: 141.73 | F21: 142.04 | G21: 152.05 | H21: =H19+H10 -> 136.53164 | I21: =I19+I10 -> 142.52713 | J21: =J19+J10 -> 148.61214 | K21: =K19+K10 -> 154.77929 | L21: =L19+L10 -> 159.04565 | M21: =AVERAGE(D22:G22) -> 0.051125421
D22: =(D21-C21)/C21 -> 0.012154166 | E22: =(E21-D21)/D21 -> 0.11968715 | F22: =(F21-E21)/E21 -> 0.0021872575 | G22: =(G21-F21)/F21 -> 0.070473106
A23: Account Payable | C23: 8.32 | D23: 8.44 | E23: 9.22 | F23: 9.54 | G23: 10.04 | H23: =G23*(1+$M$23) -> 10.526835 | I23: =H23*(1+$M$23) -> 11.037277 | J23: =I23*(1+$M$23) -> 11.572469 | K23: =J23*(1+$M$23) -> 12.133613 | L23: =K23*(1+$M$23) -> 12.721966 | M23: =AVERAGE(D24:G24) -> 0.04848955
D24: =(D23-C23)/C23 -> 0.014423077 | E24: =(E23-D23)/D23 -> 0.092417062 | F24: =(F23-E23)/E23 -> 0.034707158 | G24: =(G23-F23)/F23 -> 0.052410901
A25: Short Term Debt | C25: 1.46 | D25: 0.76 | E25: 1.57 | F25: 1.78 | G25: 1.72 | H25: =G25*(1+$M$26) -> 2.0151466 | I25: =H25*(1+$M$26) -> 2.3609395 | J25: =I25*(1+$M$26) -> 2.7660694 | K25: =J25*(1+$M$26) -> 3.2407182 | L25: =K25*(1+$M$26) -> 3.7968154
D26: =(D25-C25)/C25 -> -0.47945205 | E26: =(E25-D25)/D25 -> 1.0657895 | F26: =(F25-E25)/E25 -> 0.13375796 | G26: =(G25-F25)/F25 -> -0.033707865 | M26: =AVERAGE(D26:G26) -> 0.17159688
A29: Other | C29: 1.45 | D29: 1.28 | E29: 1.44 | F29: 1.88 | G29: 2.05 | H29: =G29*(1+$M$29) -> 2.2569166 | I29: =H29*(1+$M$29) -> 2.4847183 | J29: =I29*(1+$M$29) -> 2.7355132 | K29: =J29*(1+$M$29) -> 3.011622 | L29: =K29*(1+$M$29) -> 3.3155998 | M29: =AVERAGE(D30:G30) -> 0.10093493
D30: =(D29-C29)/C29 -> -0.11724138 | E30: =(E29-D29)/D29 -> 0.125 | F30: =(F29-E29)/E29 -> 0.30555556 | G30: =(G29-F29)/F29 -> 0.090425532
A31: Total Current Liabilities | C31: 15.85 | D31: 15.09 | E31: 17.39 | F31: 17.03 | G31: 18.71 | H31: =(H29+H25+H23) -> 14.798898 | I31: =(I29+I25+I23) -> 15.882934 | J31: =(J29+J25+J23) -> 17.074052 | K31: =(K29+K25+K23) -> 18.385953 | L31: =(L29+L25+L23) -> 19.834382 | M31: =AVERAGE(D32:G32) -> 0.045604296
C32: =AVERAGE(C31:G31) -> 16.814 | D32: =(D31-C31)/C31 -> -0.047949527 | E32: =(E31-D31)/D31 -> 0.15241882 | F32: =(F31-E31)/E31 -> -0.020701553 | G32: =(G31-F31)/F31 -> 0.098649442
A33: Long term Debt | C33: 18.65 | D33: 17.22 | E33: 17.07 | F33: 16.23 | G33: 19.36 | H33: =G33*(1+($M$33*0.33)+(Assumptions!C31*0.33)+($H$48*0.33)) -> 19.455604 | I33: =H33*(1+($M$33*0.33)+(Assumptions!D31*0.33)+($H$48*0.33)) -> 20.01068 | J33: =I33*(1+($M$33*0.33)+(Assumptions!E31*0.33)+($H$48*0.33)) -> 20.828331 | K33: =J33*(1+($M$33*0.33)+(Assumptions!F31*0.33)+($H$48*0.33)) -> 21.404792 | L33: =K33*(1+($M$33*0.33)+(Assumptions!G31*0.33)+($H$48*0.33)) -> 22.222886 | M33: =AVERAGE(D34:G34) -> 0.0145643
C34: =AVERAGE(C33:G33) -> 17.706 | D34: =(D33-C33)/C33 -> -0.076675603 | E34: =(E33-D33)/D33 -> -0.0087108014 | F34: =(F33-E33)/E33 -> -0.049209139 | G34: =(G33-F33)/F33 -> 0.19285274
A35: Other | C35: 20.26 | D35: 21.51 | E35: 23.05 | F35: 26.01 | G35: 26.73 | H35: =C36*(1+($M$33*0.33)+($Q$3*0.33)+($H$48*0.33)) -> 23.90743 | I35: =H35*(1+($M$33*0.33)+($Q$3*0.33)+($H$48*0.33)) -> 24.30951 | J35: =I35*(1+($M$33*0.33)+($Q$3*0.33)+($H$48*0.33)) -> 24.718353 | K35: =J35*(1+($M$33*0.33)+($Q$3*0.33)+($H$48*0.33)) -> 25.134072 | L35: =K35*(1+($M$33*0.33)+($Q$3*0.33)+($H$48*0.33)) -> 25.556782 | M35: =AVERAGE(D36:G36) -> 0.07234767
C36: =AVERAGE(C35:G35) -> 23.512 | D36: =(D35-C35)/C35 -> 0.061697927 | E36: =(E35-D35)/D35 -> 0.071594607 | F36: =(F35-E35)/E35 -> 0.12841649 | G36: =(G35-F35)/F35 -> 0.027681661
A37: Total Non-current L | C37: 44.77 | D37: 44.03 | E37: 46.39 | F37: 47.6 | G37: 50.61 | H37: =C38*(1+($M$37*0.33)+($Q$3*0.33)+($H$48*0.33)) -> 47.727458 | I37: =H37*(1+($M$35*0.33)+($Q$3*0.33)+($H$48*0.33)) -> 49.440241 | J37: =I37*(1+($M$35*0.33)+($Q$3*0.33)+($H$48*0.33)) -> 51.214489 | K37: =J37*(1+($M$35*0.33)+($Q$3*0.33)+($H$48*0.33)) -> 53.05241 | L37: =K37*(1+($M$35*0.33)+($Q$3*0.33)+($H$48*0.33)) -> 54.956288 | M37: =AVERAGE(D38:G38) -> 0.031597349
C38: =AVERAGE(C37:G37) -> 46.68 | D38: =(D37-C37)/C37 -> -0.016528926 | E38: =(E37-D37)/D37 -> 0.053599818 | F38: =(F37-E37)/E37 -> 0.026083208 | G38: =(G37-F37)/F37 -> 0.063235294
A39: Total Liabilities | C39: 60.62 | D39: 59.12 | E39: 63.78 | F39: 64.63 | G39: 69.32 | H39: =H31+H37 -> 62.526357 | I39: =I31+I37 -> 65.323175 | J39: =J31+J37 -> 68.288541 | K39: =K31+K37 -> 71.438363 | L39: =L31+L37 -> 74.790669 | M39: =AVERAGE(D40:G40) -> 0.034993101
D40: =(D39-C39)/C39 -> -0.024744309 | E40: =(E39-D39)/D39 -> 0.078822733 | F40: =(F39-E39)/E39 -> 0.013327062 | G40: =(G39-F39)/F39 -> 0.072566919
A42: Equity | C42: 64.44 | D42: 67.46 | E42: 77.95 | F42: 77.41 | G42: 82.73 | H42: =H21-H39 -> 74.005287 | I42: =I21-I39 -> 77.20395 | J42: =J21-J39 -> 80.3236 | K42: =K21-K39 -> 83.340928 | L42: =L21-L39 -> 84.254984 | M42: =AVERAGE(D43:G43) -> 0.066040577
A43: growth % | D43: =(D42-C42)/C42 -> 0.046865301 | E43: =(E42-D42)/D42 -> 0.15549956 | F43: =(F42-E42)/E42 -> -0.0069275176 | G43: =(G42-F42)/F42 -> 0.068724971 | I43: =(I42-H42)/I42 -> 0.041431333 | J43: =(J42-I42)/J42 -> 0.038838526 | K43: =(K42-J42)/K42 -> 0.036204639 | L43: =(L42-K42)/L42 -> 0.01084868
A45: Specific Assumptions: | J45: `
A46: Cash = Net Income/Cash Ratio | C46: 17.875 | D46: 28.137 | E46: 14.199 | F46: 11.525 | G46: 18.274 | H46: Averate ratio
...

Sheet Beta
B1: RIO.AX History | C1: Weekly 5 Years | E1: ASX | H1: RIO.L History | I1: Weekly 5 Years | K1: FTSE
C2: Exchange Date | D2: %Chg | E2: %Chg | I2: Exchange Date | J2: %Chg | K2: %Chg
C3: 09-Aug-2019 | I3: 09-Aug-2019 | S3: Average Monthly and Weekly BETA
C4: 16-Aug-2019 | D4: -0.03387 | E4: -0.02717 | I4: 16-Aug-2019 | J4: -0.0126 | K4: -0.0188 | M4: SUMMARY OUTPUT | O4: RIO.AX | P4: WEEKLY | S4: =AVERAGE(N21,O285) -> 0.59689216
C5: 23-Aug-2019 | D5: 0.00331 | E5: 0.01836 | I5: 23-Aug-2019 | J5: -0.0201 | K5: -0.0031
C6: 30-Aug-2019 | D6: 0.03035 | E6: 0.01243 | I6: 30-Aug-2019 | J6: 0.0573 | K6: 0.0158 | M6: Regression Statistics
C7: 06-Sep-2019 | D7: 0.03186 | E7: 0.00653 | I7: 06-Sep-2019 | J7: 0.0211 | K7: 0.0104 | M7: Multiple R | N7: 0.4473964
C8: 13-Sep-2019 | D8: 0.03231 | E8: 0.00329 | I8: 13-Sep-2019 | J8: 0.0445 | K8: 0.0117 | M8: R Square | N8: 0.20016354
C9: 20-Sep-2019 | D9: -0.00911 | E9: 0.00924 | I9: 20-Sep-2019 | J9: -0.0435 | K9: -0.0031 | M9: Adjusted R Square | N9: 0.19707537
C10: 27-Sep-2019 | D10: -0.00909 | E10: -0.00218 | I10: 27-Sep-2019 | J10: 0.0039 | K10: 0.0111 | M10: Standard Error | N10: 0.032341725
C11: 04-Oct-2019 | D11: -0.04312 | E11: -0.02963 | I11: 04-Oct-2019 | J11: -0.0504 | K11: -0.0365 | M11: Observations | N11: 261
C12: 11-Oct-2019 | D12: 0.02647 | E12: 0.01376 | I12: 11-Oct-2019 | J12: 0.0431 | K12: 0.0128
C13: 18-Oct-2019 | D13: -0.02334 | E13: 0.00649 | I13: 18-Oct-2019 | J13: -0.0589 | K13: -0.0133 | M13: ANOVA
C14: 25-Oct-2019 | D14: 0.03346 | E14: 0.01346 | I14: 25-Oct-2019 | J14: 0.0395 | K14: 0.0243 | N14: df | O14: SS | P14: MS | Q14: F | R14: Significance F
C15: 43770 | D15: -0.00352 | E15: -0.0104 | I15: 43770 | J15: 0.0121 | K15: -0.003 | M15: Regression | N15: 1 | O15: 0.06779691 | P15: 0.06779691 | Q15: 64.816197 | R15: 2.99516e-14
C16: 43777 | D16: 0.05238 | E16: 0.00825 | I16: 43777 | J16: 0.0091 | K16: 0.0078 | M16: Residual | N16: 259 | O16: 0.27091067 | P16: 0.001045987
C17: 43784 | D17: -0.01775 | E17: 0.01035 | I17: 43784 | J17: -0.0122 | K17: -0.0077 | M17: Total | N17: 260 | O17: 0.33870758
C18: 43791 | D18: 0.00545 | E18: -0.01235 | I18: 43791 | J18: 0.0072 | K18: 0.0033
C19: 43798 | D19: 0.0303 | E19: 0.0203 | I19: 43798 | J19: 0.0041 | K19: 0.0027 | N19: Coefficients | O19: Standard Error | P19: t Stat | Q19: P-value | R19: Lower 95% | S19: Upper 95% | T19: Lower 95,0% | U19: Upper 95,0%
C20: 06-Dec-2019 | D20: -0.01146 | E20: -0.0203 | I20: 06-Dec-2019 | J20: 0.0036 | K20: -0.0145 | M20: Intercept | N20: 0.001299675 | O20: 0.002003425 | P20: 0.64872653 | Q20: 0.51708994 | R20: -0.002645401 | S20: 0.00524475 | T20: -0.002645401 | U20: 0.00524475
C21: 13-Dec-2019 | D21: 0.05021 | E21: 0.00488 | I21: 13-Dec-2019 | J21: 0.0247 | K21: 0.0157 | M21: X Variable 1 | N21: 0.73916096 | O21: 0.091811534 | P21: 8.0508507 | Q21: 2.99516e-14 | R21: 0.55836885 | S21: 0.91995307 | T21: 0.55836885 | U21: 0.91995307
C22: 20-Dec-2019 | D22: 0.03042 | E22: 0.01137 | I22: 20-Dec-2019 | J22: 0.0492 | K22: 0.0311
C23: 27-Dec-2019 | D23: -0.01109 | E23: 0.00079 | I23: 27-Dec-2019 | J23: 0.0034 | K23: 0.0082
C24: 03-Jan-2020 | D24: -0.01122 | E24: -0.01293 | I24: 03-Jan-2020 | J24: -0.0098 | K24: -0.0029
C25: 10-Jan-2020 | D25: 0.01056 | E25: 0.02903 | I25: 10-Jan-2020 | J25: -0.0036 | K25: -0.0045 | M25: SUMMARY OUTPUT | O25: RIO.L | P25: WEEKLY
C26: 17-Jan-2020 | D26: 0.02743 | E26: 0.0195 | I26: 17-Jan-2020 | J26: 0.0363 | K26: 0.0114
C27: 24-Jan-2020 | D27: -0.01957 | E27: 0.00374 | I27: 24-Jan-2020 | J27: -0.0457 | K27: -0.0115 | M27: Regression Statistics
C28: 31-Jan-2020 | D28: -0.04274 | E28: -0.01034 | I28: 31-Jan-2020 | J28: -0.0799 | K28: -0.0395 | M28: Multiple R | N28: 0.56509469
C29: 43868 | D29: -0.00344 | E29: 0.00077 | I29: 43868 | J29: 0.0252 | K29: 0.0248 | M29: R Square | N29: 0.319332
C30: 43875 | D30: -0.00792 | E30: 0.01532 | I30: 43875 | J30: 0.0024 | K30: -0.0077 | M30: Adjusted R Square | N30: 0.31670394
C31: 43882 | D31: 0.00041 | E31: 0.00123 | I31: 43882 | J31: 0.0013 | K31: -0.0007 | M31: Standard Error | N31: 0.033481736
C32: 43889 | D32: -0.10666 | E32: -0.09774 | I32: 43889 | J32: -0.1415 | K32: -0.1112 | M32: Observations | N32: 261
C33: 43896 | D33: -0.01169 | E33: -0.03493 | I33: 43896 | J33: -0.0285 | K33: -0.0179
C34: 43903 | D34: -0.05994 | E34: -0.10889 | I34: 43903 | J34: -0.0659 | K34: -0.1697 | M34: ANOVA
C35: 43910 | D35: 0.01135 | E35: -0.13047 | I35: 43910 | J35: -0.0189 | K35: -0.0327 | N35: df | O35: SS | P35: MS | Q35: F | R35: Significance F
C36: 43917 | D36: 0.0461 | E36: 0.00536 | I36: 43917 | J36: 0.0984 | K36: 0.0616 | M36: Regression | N36: 1 | O36: 0.13621433 | P36: 0.13621433 | Q36: 121.50856 | R36: 2.01557e-23
C37: 43924 | D37: 0.03672 | E37: 0.04649 | I37: 43924 | J37: 0.066 | K37: -0.0172 | M37: Residual | N37: 259 | O37: 0.2903459 | P37: 0.001121027
C38: 43931 | D38: 0.00517 | E38: 0.06311 | I38: 43931 | J38: 0.0245 | K38: 0.0789 | M38: Total | N38: 260 | O38: 0.42656023
C39: 43938 | D39: 0.02372 | E39: 0.0186 | I39: 43938 | J39: -0.0095 | K39: -0.0095
C40: 43945 | D40: -0.04633 | E40: -0.04463 | I40: 43945 | J40: -0.0174 | K40: -0.006 | N40: Coefficients | O40: Standard Error | P40: t Stat | Q40: P-value | R40: Lower 95% | S40: Upper 95% | T40: Lower 95,0% | U40: Upper 95,0%
...

Sheet Debt
G1: Weighted Average Coupon | L1: `
E2: Interest Expense | G2: 4.857
A3: Rio.ax | B3: Bonds Issued (Debt) | E3: 2024 | F3: 2025 | G3: 2026 | H3: 2027 | I3: 2028 | P3: 2011 | Q3: Issued Amount | R3: Coupon
A4: 2028 | B4: Issued Amount | C4: Coupon | D4: Coupon Class | Q4: 41203153 | R4: 9.5
B5: 1115407496 | C5: 7.125 | D5: Fixed Coupon | E5: 79472784 | F5: 79472784 | G5: 79472784 | H5: 79472784 | I5: 79472784
A6: 2040 | B6: Issued Amount | C6: Coupon | D6: Coupon Class | P6: 2013 | Q6: Issued Amount | R6: Coupon
B7: 1710291493 | C7: 5.2 | D7: Fixed Coupon | E7: 88935158 | F7: 88935158 | G7: 88935158 | H7: 88935158 | I7: 88935158 | Q7: 82406306 | R7: 0
A8: 2051 | B8: Issued Amount | C8: Coupon | D8: Coupon Class
B9: 1859012493 | C9: 2.75 | D9: Fixed Coupon | E9: 51122844
A10: TOTAL | B10: =SUM(B5,B7,B9) -> 4684711482 | E10: =SUM(E5:E9) -> 219530786 | F10: =SUM(F5:F9) -> 1.6840794e+08 | G10: =SUM(G5:G9) -> 1.6840794e+08 | H10: =SUM(H5:H9) -> 1.6840794e+08 | I10: =SUM(I5:I9) -> 1.6840794e+08
A12: Rio.plc | B12: Bonds Issued (Debt)
A13: 2024 | B13: Issued Amount | C13: Coupon | D13: Coupon Class
B14: 824063058 | C14: 2.875 | D14: Fixed Coupon | E14: 23691813 | F14: 0 | G14: 0 | H14: 0 | I14: 0
A15: 2028 | B15: Issued Amount | C15: Coupon | D15: Coupon Class
B16: 148720999 | C16: 7.25 | D16: Fixed Coupon | E16: 23691813 | F16: 0 | G16: 0 | H16: 0 | I16: 0
A17: 2029 | B17: Issued Amount | C17: Coupon | D17: Coupon Class
B18: 977245687 | C18: 4 | D18: Fixed Coupon | E18: 39089827 | F18: 39089827 | G18: 39089827 | H18: 39089827 | I18: 39089827
A19: 2031 | B19: Issued Amount | C19: Coupon | D19: Coupon Class
B20: 594883998 | C20: 7.25 | D20: Fixed Coupon | E20: 43129090 | F20: 43129090 | G20: 43129090 | H20: 43129090 | I20: 43129090
A21: 2033 | B21: Issued Amount | C21: Coupon | D21: Coupon Class
B22: 966686496 | C22: 5 | D22: Fixed Coupon | E22: 48334325 | F22: 48334325 | G22: 48334325 | H22: 48334325 | I22: 48334325
B23: 1115407496 | C23: 6.125 | D23: Fixed Coupon | E23: 68318709 | F23: 68318709 | G23: 68318709 | H23: 68318709 | I23: 68318709
A24: 2035 | B24: Issued Amount | C24: Coupon | D24: Coupon Class
B25: 446162998 | C25: 5.75 | D25: Fixed Coupon | E25: 25654372 | F25: 25654372 | G25: 25654372 | H25: 25654372 | I25: 25654372
A26: 2042 | B26: Issued Amount | C26: Coupon | D26: Coupon Class
B27: 743604997 | C27: 4.75 | D27: Fixed Coupon | E27: 35321237 | F27: 35321237 | G27: 35321237 | H27: 35321237 | I27: 35321237
B28: 1115407496 | C28: 4.125 | D28: Fixed Coupon | E28: 46010559 | F28: 46010559 | G28: 46010559 | H28: 46010559 | I28: 46010559
A29: 2053 | B29: Issued Amount | C29: Coupon | D29: Coupon Class
B30: 1635930993 | C30: 5.125 | D30: Fixed Coupon | E30: 83841463 | F30: 83841463 | G30: 83841463 | H30: 83841463 | I30: 83841463
A31: Total | B31: =SUM(B14,B16,B18,B20,B22,B23,B25,B27,B28,B30) -> 8568114218 | E31: 643704454 | F31: 568889798 | G31: 568889798 | H31: 568889798 | I31: 568889798
A32: Total Issued | B32: =B31+B10 -> 13252825700 | E32: =E31+E10 -> 863235240 | F32: =F31+F10 -> 7.3729774e+08 | G32: =G31+G10 -> 7.3729774e+08 | H32: =H31+H10 -> 7.3729774e+08 | I32: =I31+I10 -> 7.3729774e+08

Sheet WACC
B2: Bonds | C2: Loans | D2: TOTAL DEBT BALANCE SHEET | F2: Mark cap= Total Equity= | J2: Mark Premium | K2: BETA | L2: Tax rate | M2: W debt | N2: Cost of debt Ref
B3: 13252825700 | C3: 28443745745 | D3: =19360000000 -> 19360000000 | F3: 151669152823 | J3: 5 | K3: =Beta!$S$4 -> 0.59689216 | L3: =0.3 -> 0.3 | M3: 4.857 | N3: 3.383
K5: BETA (industry)
B7: Cost of debt Ref | D7: 3.383
B8: W debt | D8: 4.857 | F8: =(D3)/(F3+D3) -> 0.11319708
B9: Tax rate | D9: =0.3 -> 0.3 | F9: =1-F8 -> 0.88680292
B10: BETA | D10: =Beta!$S$4 -> 0.59689216
B11: BETA (industry) | D11: =0.66*1 + 0.33*K3 -> 0.85697441
B12: Mark Premium | D12: 5
B13: AUS 10 Yr Bond | D13: 4.326
B14: Cost Of Equity | D14: =D13+K3*J3 -> 7.3104608
B15: Cost Of Equity (industry) | D15: =D13+D11*J3 -> 8.6108721
B16: Cost Of Debt | D16: =AVERAGE(M3:N3) -> 4.12
B17: WACC | D17: =D16*(D3)/(F3+D3)*(1-L3)+F3*D14/(F3+D3) -> 6.8093984
B18: WACC (industry) | D18: =D16*(D3)/(F3+D3)*(1-L3)+F3*D15/(F3+D3) -> 7.9626069
B19: london WACC | D19: 0.08

Sheet TGR
A1: TGR Growth Rate
A2: Global Inflation 2028 | D2: =3.4 % -> 0.034
A3: Industry CAGR by 2028 Globally | D3: 0.055
A4: G7 GDP | D4: =1.73 % -> 0.0173
A5: CEO CAGR exp (analysts call) | D5: 0.03
A6: TGR | D6: =0.25*D2+0.25*D3+0.25*D4+0.25*D5 -> 0.034075

Sheet DCF
B2: DCF (in billions AUD)
A3: Years | B3: 1 | C3: 2 | D3: 3 | E3: 4 | F3: 5 | I3: WACC | J3: =WACC!D17/100 -> 0.068093984
B4: 2024 | C4: 2025 | D4: 2026 | E4: 2027 | F4: 2028 | G4: TV | I4: TGR | J4: =TGR!D6 -> 0.034075
A6: EBIT | B6: {='Income Statement'!H19:L19} -> 27.3974 | C6: 22.959877 | D6: 19.196407 | E6: 21.228941 | F6: 25.484009
A7: Dep + Am | B7: ='Income Statement'!H34 -> 8.7586829 | C7: ='Income Statement'!I34 -> 9.5451694 | D7: ='Income Statement'!J34 -> 10.402279 | E7: ='Income Statement'!K34 -> 11.336352 | F7: ='Income Statement'!L34 -> 12.3543
A8: Delta WC | B8: ='Balance Sheet'!H10-'Balance Sheet'!H31 -> 13.845778 | C8: ='Balance Sheet'!I10-'Balance Sheet'!I31 -> 15.014235 | D8: ='Balance Sheet'!J10-'Balance Sheet'!J31 -> 16.082033 | E8: ='Balance Sheet'!K10-'Balance Sheet'!K31 -> 17.035905 | F8: ='Balance Sheet'!L10-'Balance Sheet'!L31 -> 15.860571
A9: CapEx | B9: =('Balance Sheet'!H13-'Balance Sheet'!G13)+'Income Statement'!H34 -> 12.219948 | C9: =('Balance Sheet'!I13-'Balance Sheet'!H13)+'Income Statement'!I34 -> 13.073936 | D9: =('Balance Sheet'!J13-'Balance Sheet'!I13)+'Income Statement'!J34 -> 14.007434 | E9: =('Balance Sheet'!K13-'Balance Sheet'!J13)+'Income Statement'!K34 -> 15.00985 | F9: =('Balance Sheet'!L13-'Balance Sheet'!K13)+'Income Statement'!L34 -> 16.112535
C10: =C9/B9-1 -> 0.06988474 | D10: =D9/C9-1 -> 0.071401494 | E10: =E9/D9-1 -> 0.071563122 | F10: =F9/E9-1 -> 0.073464113 | H10: =AVERAGE(C10:F10) -> 0.071578367
A11: Free Cash Flow | B11: =B6+B7-B8-B9 -> 10.090357 | C11: =C6+C7-C8-C9 -> 4.416876 | D11: =D6+D7-D8-D9 -> -0.49078185 | E11: =E6+E7-E8-E9 -> 0.51953856 | F11: =F6+F7-F8-F9 -> 5.8652028
A12: Discount rate | B12: 0.0681 | C12: 0.0681 | D12: 0.0681 | E12: 0.0681 | F12: 0.0681
A13: TGR | B13: =TGR!$D$6 -> 0.034075 | C13: =TGR!$D$6 -> 0.034075 | D13: =TGR!$D$6 -> 0.034075 | E13: =TGR!$D$6 -> 0.034075 | F13: =TGR!$D$6 -> 0.034075 | G13: =TGR!$D$6 -> 0.034075
A14: Terminal Value | G14: =F11/(J3-J4) -> 172.4097
A15: DCF | B15: =(B11/(1+$J$3)^B3) -> 9.4470685 | C15: =(C11/(1+$J$3)^C3) -> 3.8716516 | D15: =(D11/(1+$J$3)^D3) -> -0.40277276 | E15: =(E11/(1+$J$3)^E3) -> 0.39919023 | F15: =(F11/(1+$J$3)^F3) -> 4.2192542 | G15: =(F11+G14)/(1+$J$3)^F3 -> 128.24571
A16: Enterprise Value | B16: =SUM(B15:G15) -> 145.78011
A17: Deduct: LTD | B17: ='Balance Sheet'!H33 -> 19.455604
A18: Add: Cash | B18: ='Balance Sheet'!H2 -> 17.24591
A19: No. of shares | B19: =Multiplies!K5 -> 1.51
A20: Intrinsic Value | B20: =(B16-B17+B18)/B19 -> 95.079744
A21: Price as at 12/09/2024 | B21: =Multiplies!K7 -> 110.41
A22: Upside | B22: =B20/B21-1 -> -0.13884844

Sheet Multiplies
D3: RV Valuation | E3: 2023 | F3: 2024 | H3: 2023 | I3: 2024
C4: Ticker | D4: Name | E4: P/E | F4: Fwd P/E | H4: EV/EBITDA | I4: Forward EV/EBITDA | K4: Shares Outstanding | M4: P/E = price of share/ EPS
C5: BHP.AX | D5: Deterra Royalties Ltd | E5: 12.714963 | F5: 12.407805 | H5: 9.1211014 | I5: 7.9780887 | K5: 1.51 | M5: EV/EBITDA = EV divide EBITDA EV = equity value + Net Debt
C6: CRN.AX | D6: BHP Group Ltd | E6: 9.8639419 | F6: 10.865665 | H6: 7.8497463 | I6: 5.1209518 | K6: Share Price 12/09/24 | M6: eps = Net Income divide shares outstanding
C7: DRR.AX | D7: Fortescue Ltd | E7: 6.361304 | F7: 9.546719 | H7: 4.1619958 | I7: 4.5626625 | K7: 110.41
C8: FMG.AX | D8: Coronado Global Resources Inc | E8: -41.335148 | F8: 6.9363973 | H8: 5.6117657 | I8: 3.7539284
C9: WHC.AX | D9: Whitehaven Coal Ltd | E9: 6.57178 | F9: 7.4497821 | H9: 5.6248188 | I9: 3.3137793
C10: GLEN.L | D10: Glencore PLC | E10: 15.683009 | F10: 11.317152 | H10: 7.0173621 | I10: 5.4686113
C11: NEM | D11: Newmont Corporation | E11: 24.910798 | F11: 14.990193 | H11: 14.051879 | I11: 8.2028647
C12: AAL.L | D12: Anglo American PLC | E12: 13.42373 | F12: 12.478388 | H12: 5.5159186 | I12: 5.829911
C13: VALE3.SA | D13: Vale SA | E13: 4.6620115 | F13: 4.7965155 | H13: 4.1839679 | I13: 3.452361
D14: Median | E14: =MEDIAN(E5:E9) -> 6.57178 | F14: =MEDIAN(F5:F9) -> 9.546719 | H14: =MEDIAN(H5:H13) -> 5.6248188 | I14: =MEDIAN(I5:I13) -> 5.1209518 | N14: 2023 | O14: Forward
C15: RIO.AX | D15: Rio Tinto Ltd | E15: =N20 -> 9.1232954 | F15: =O20 -> 10.614494 | H15: =N22 -> 4.9815968 | I15: =O22 -> 4.6110941 | M15: EBITDA | N15: ='Income Statement'!G38 -> 33.467 | O15: ='Income Statement'!H38 -> 36.156083
D16: Historical Premium | E16: =(E15/E14)-1 -> 0.38825332 | F16: =(F15/F14)-1 -> 0.11184735 | H16: =(H15/H14)-1 -> -0.11435427 | I16: =(I15/I14)-1 -> -0.099563065 | M16: Shares Outstanding | N16: 1.51 | O16: 1.51
D17: Target | E17: =E15*(1+E16) -> 12.665445 | F17: =F15*(1+F16) -> 11.801697 | H17: =H15*(1+H16) -> 4.4119299 | I17: =I15*(1+I16) -> 4.1519994
M18: Ratios | N18: 2023 | O18: Forward - 2024
C19: RIO.AX | D19: Rio Tinto Ltd | E19: EPS | F19: Fwd EPS | H19: Ebitda | I19: Forward EBITDA | M19: eps | N19: ='Income Statement'!G31/Multiplies!K5 -> 12.101987 | O19: ='Income Statement'!H31/K5 -> 10.401814
E20: =N19 -> 12.101987 | F20: =O19 -> 10.401814 | H20: =N15 -> 33.467 | I20: =O15 -> 36.156083 | M20: P/E | N20: =K7/N19 -> 9.1232954 | O20: =K7/O19 -> 10.614494
G21: Implied EV | H21: =H20*H17 -> 147.65406 | I21: =I20*I17 -> 150.12004 | M21: EV | N21: =K7*K5 -> 166.7191 | O21: =K7*K5 -> 166.7191
G22: ltd | H22: ='Balance Sheet'!G33 -> 19.36 | I22: ='Balance Sheet'!H33 -> 19.455604 | M22: EV/EBITDA | N22: =N21/'Income Statement'!G38 -> 4.9815968 | O22: =O21/O15 -> 4.6110941
D23: Intrinsic Value Per Share | E23: =E20*E17 -> 153.27705 | F23: =F20*E17 -> 131.74361 | G23: Intrinsic Value Per Share | H23: =(H21-H22)/K5 -> 84.962953 | I23: =(I21-I22)/K5 -> 86.532736
D24: Weight | E24: 0.5 | F24: 0.5 | H24: 0.5 | I24: 0.5
D25: Intrinsic Value Per Share | E25: =(E23*E24)+(F23*F24) -> 142.51033 | G25: Intrinsic Value Per Share | H25: =(H23*H24)+(I23*I24) -> 85.747845
D26: Current Share Price | E26: =K7 -> 110.41
D27: Intrinsic Value | E27: =AVERAGE(E25,H25) -> 114.12909
D28: Upside | E28: =(E27-E26)/E26 -> 0.033684332
